Workbook

Sheet Summary
A1: Dunkerque–Barcelona chain: base-to-base confirmation
A2: Source: Delambre, Base du système métrique décimal, Tome II (1807): Tableau complet des triangles pp. 800–839; Calcul des triangles pp. 701–705. Tome I (1806) Tableau des triangles pp. 513–542 for the original angles.
A4: Constants
A5: Mean degree used by Delambre (toises) | C5: 57020 | D5: “degré moyen de 57020 t”, Tome II p. 706
A6: Sphere radius R (toises) | C6: =C5*180/PI() -> 3267005.3 | D6: Used to turn log sin (sines in toises) into arcs
A7: Metres per toise | C7: =10^0.2898199927 -> 1.9490366 | D7: Delambre’s logarithm constant 0.28981.99927, Tome II p. 839
A8: Toise in pouces / lignes | C8: 72 | D8: 864 | E8: 1 toise = 6 pieds = 72 pouces = 864 lignes
A10: Melun base (Lieursaint–Melun, triangle 43)
B11: log sin | C11: toises | D11: metres
A12: Measured (enters the table) | B12: =Chain!N131 -> 3.7836104 | C12: =$C$6*ASIN(10^B12/$C$6) -> 6075.9001 | D12: =C12*$C$7 -> 11842.152 | E12: Delambre fixed his scale constant so these agree (p. 702); the 0.005 mm residue is rounding in the last logarithm digits.
A13: Carried from Dunkerque through triangles 1–42 | B13: =Chain!O131 -> 3.7836104 | C13: =$C$6*ASIN(10^B13/$C$6) -> 6075.9001 | D13: =C13*$C$7 -> 11842.152
A14: Difference (mm) | D14: =(D13-D12)*1000 -> -0.0054536649
A15: Base length on the measurement pages (arc, p. 44) | C15: 6075.8973 | D15: =C15*$C$7 -> 11842.146 | E15: 2.8 mm shorter than the value used in the triangles (6075.9001). See the Melun reduction workbook.
A17: Perpignan base (Vernet–Salces, triangle 104): the confirmation
B18: log sin | C18: toises | D18: metres | E18: Delambre (p. 703)
A19: Measured | B19: 3.7786031 | C19: =$C$6*ASIN(10^B19/$C$6) -> 6006.2487 | D19: =C19*$C$7 -> 11706.398 | E19: 3.77860.30659
A20: Carried from Melun — original angles (Tome I) | B20: =Chain!S314 -> 3.7785923 | C20: =$C$6*ASIN(10^B20/$C$6) -> 6006.1002 | D20: =C20*$C$7 -> 11706.109 | E20: 3.77859.23288
A21: Carried from Melun — adjusted angles (Tome II) | B21: =Chain!O314 -> 3.7786031 | C21: =$C$6*ASIN(10^B21/$C$6) -> 6006.2485 | D21: =C21*$C$7 -> 11706.398 | E21: “je me trouvai juste à Perpignan”
A22: Carried from Melun — Tome II angles, log sines recomputed from the angles | B22: =Chain!T314 -> 3.7786019 | C22: =$C$6*ASIN(10^B22/$C$6) -> 6006.2328 | D22: =C22*$C$7 -> 11706.368 | E22: (not given)
A24: Confirmation: measured − carried (original angles) | B24: =B19-B20 -> 1.0737943e-05 | C24: =C19-C20 -> 0.148503 | D24: =D19-D20 -> 0.28943778 | E24: Delambre: 0.00001.07371 = 0ᵗ14849 = 10 pouces 8.3 lignes
A25: in pouces | C25: =C24*$C$8 -> 10.692216
A26: in lignes | C26: =C24*$D$8 -> 128.30659
A27: relative to the length of the base (ppm) | C27: =C24/C19*1000000 -> 24.72475
A28: Agreement of my recomputation with Delambre’s 3.77859.23288 (mm) | C28: =(B20-3.7785923288)*LN(10)*C20*$C$7*1000 -> -0.022726121
A30: Effect of the adjustment (adjusted − original angles, toises) | C30: =C21-C20 -> 0.1483481
A31: Effect of the angle/log-sine mismatches in triangles 52–54 (toises) | C31: =C22-C21 -> -0.015706585 | E31: Delambre’s printed log sines for three near-90° angles do not match the printed angles (Source notes). Recomputing them moves Perpignan by this much.
A32: Base length on the measurement pages (arc, p. 55) | C32: 6006.2554 | D32: =C32*$C$7 -> 11706.412 | E32: The value used for the comparison (6006.2487) is 6.8 mm shorter; Delambre trims 0.003–0.005 t for ruler thickness on p. 55.
A34: Checks
A35: Largest |chain − printed| on the main chain (×1e-10, excluding listed source slips) | C35: =MAX(ABS(Chain!P6),ABS(Chain!P7),ABS(Chain!P8),ABS(Chain!P9),ABS(Chain!P11),ABS(Chain!P12),ABS(Chain!P14),ABS(Chain!P15),ABS(Chain!P17),ABS(Chain!P18),ABS(Chain!P20),ABS(Chain!P21),ABS(Chain!P23),ABS(Chain!P25),ABS(Chain!P27),ABS(Chain!P28),ABS(Chain!P29),ABS(Chain!P31),ABS(Chain!P32),ABS(Chain!P33),ABS(Chain!P35),ABS(Chain!P36),ABS(Chain!P38),ABS(Chain!P39),ABS(Chain!P41),ABS(Chain!P42),ABS(Chain!P44),ABS(Chain!P45),ABS(Chain!P47),ABS(Chain!P49),ABS(Chain!P50),ABS(Chain!P52),ABS(Chain!P53),ABS(Chain!P54),ABS(Chain!P56),ABS(Chain!P57),ABS(Chain!P59),ABS(Chain!P60),ABS(Chain!P62),ABS(Chain!P63),ABS(Chain!P65),ABS(Chain!P66),ABS(Chain!P68),ABS(Chain!P69),ABS(Chain!P71),ABS(Chain!P72),ABS(Chain!P74),ABS(Chain!P75),ABS(Chain!P77),ABS(Chain!P78),ABS(Chain!P80),ABS(Chain!P81),ABS(Chain!P83),ABS(Chain!P84),ABS(Chain!P86),ABS(Chain!P87),ABS(Chain!P89),ABS(Chain!P90),ABS(Chain!P92)) -> 3.0000269
A36: (second half of the chain) | C36: =MAX(ABS(Chain!P93),ABS(Chain!P95),ABS(Chain!P96),ABS(Chain!P98),ABS(Chain!P100),ABS(Chain!P101),ABS(Chain!P102),ABS(Chain!P105),ABS(Chain!P106),ABS(Chain!P107),ABS(Chain!P108),ABS(Chain!P110),ABS(Chain!P111),ABS(Chain!P113),ABS(Chain!P114),ABS(Chain!P116),ABS(Chain!P117),ABS(Chain!P119),ABS(Chain!P120),ABS(Chain!P125),ABS(Chain!P126),ABS(Chain!P128),ABS(Chain!P129),ABS(Chain!P131),ABS(Chain!P132),ABS(Chain!P134),ABS(Chain!P135),ABS(Chain!P137),ABS(Chain!P138),ABS(Chain!P140),ABS(Chain!P141),ABS(Chain!P143),ABS(Chain!P144),ABS(Chain!P146),ABS(Chain!P147),ABS(Chain!P149),ABS(Chain!P150),ABS(Chain!P152),ABS(Chain!P153),ABS(Chain!P158),ABS(Chain!P159),ABS(Chain!P161),ABS(Chain!P162),ABS(Chain!P164),ABS(Chain!P165),ABS(Chain!P167),ABS(Chain!P168),ABS(Chain!P170),ABS(Chain!P171),ABS(Chain!P173),ABS(Chain!P174),ABS(Chain!P176),ABS(Chain!P177),ABS(Chain!P185),ABS(Chain!P186),ABS(Chain!P188),ABS(Chain!P189),ABS(Chain!P194),ABS(Chain!P195),ABS(Chain!P197),ABS(Chain!P198),ABS(Chain!P200),ABS(Chain!P201),ABS(Chain!P209),ABS(Chain!P210),ABS(Chain!P212),ABS(Chain!P213),ABS(Chain!P215),ABS(Chain!P216),ABS(Chain!P218),ABS(Chain!P219),ABS(Chain!P221),ABS(Chain!P222),ABS(Chain!P224),ABS(Chain!P225),ABS(Chain!P227),ABS(Chain!P228),ABS(Chain!P230),ABS(Chain!P231),ABS(Chain!P233),ABS(Chain!P234),ABS(Chain!P236),ABS(Chain!P237),ABS(Chain!P239),ABS(Chain!P240),ABS(Chain!P242),ABS(Chain!P243),ABS(Chain!P245),ABS(Chain!P246),ABS(Chain!P248),ABS(Chain!P249),ABS(Chain!P251),ABS(Chain!P252),ABS(Chain!P254),ABS(Chain!P255),ABS(Chain!P257),ABS(Chain!P258),ABS(Chain!P260),ABS(Chain!P261),ABS(Chain!P263),ABS(Chain!P264),ABS(Chain!P266),ABS(Chain!P267),ABS(Chain!P269),ABS(Chain!P270),ABS(Chain!P272),ABS(Chain!P273),ABS(Chain!P275),ABS(Chain!P276),ABS(Chain!P278),ABS(Chain!P279),ABS(Chain!P281),ABS(Chain!P282),ABS(Chain!P284),ABS(Chain!P285),ABS(Chain!P287),ABS(Chain!P288),ABS(Chain!P290),ABS(Chain!P291),ABS(Chain!P293),ABS(Chain!P294),ABS(Chain!P296),ABS(Chain!P297),ABS(Chain!P299),ABS(Chain!P300),ABS(Chain!P302),ABS(Chain!P303),ABS(Chain!P305),ABS(Chain!P306),ABS(Chain!P308),ABS(Chain!P309),ABS(Chain!P311),ABS(Chain!P312),ABS(Chain!P314),ABS(Chain!P315),ABS(Chain!P317),ABS(Chain!P318),ABS(Chain!P320),ABS(Chain!P321),ABS(Chain!P323),ABS(Chain!P324),ABS(Chain!P326),ABS(Chain!P327),ABS(Chain!P329),ABS(Chain!P330),ABS(Chain!P332),ABS(Chain!P333),ABS(Chain!P335),ABS(Chain!P336),ABS(Chain!P338),ABS(Chain!P339),ABS(Chain!P341),ABS(Chain!P342),ABS(Chain!P344),ABS(Chain!P345),ABS(Chain!P347),ABS(Chain!P348)) -> 15.99993
A37: Largest angle-sum error, all triangles (″) | C37: =MAX(ABS(Chain!Y5),ABS(Chain!Y8),ABS(Chain!Y11),ABS(Chain!Y14),ABS(Chain!Y17),ABS(Chain!Y20),ABS(Chain!Y23),ABS(Chain!Y26),ABS(Chain!Y29),ABS(Chain!Y32),ABS(Chain!Y35),ABS(Chain!Y38),ABS(Chain!Y41),ABS(Chain!Y44),ABS(Chain!Y47),ABS(Chain!Y50),ABS(Chain!Y53),ABS(Chain!Y56),ABS(Chain!Y59),ABS(Chain!Y62),ABS(Chain!Y65),ABS(Chain!Y68),ABS(Chain!Y71),ABS(Chain!Y74),ABS(Chain!Y77),ABS(Chain!Y80),ABS(Chain!Y83),ABS(Chain!Y86),ABS(Chain!Y89),ABS(Chain!Y92),ABS(Chain!Y95),ABS(Chain!Y98),ABS(Chain!Y101),ABS(Chain!Y104),ABS(Chain!Y107),ABS(Chain!Y110),ABS(Chain!Y113),ABS(Chain!Y116),ABS(Chain!Y119),ABS(Chain!Y122),ABS(Chain!Y125),ABS(Chain!Y128),ABS(Chain!Y131),ABS(Chain!Y134),ABS(Chain!Y137),ABS(Chain!Y140),ABS(Chain!Y143),ABS(Chain!Y146),ABS(Chain!Y149),ABS(Chain!Y152),ABS(Chain!Y155),ABS(Chain!Y158),ABS(Chain!Y161),ABS(Chain!Y164),ABS(Chain!Y167),ABS(Chain!Y170),ABS(Chain!Y173),ABS(Chain!Y176),ABS(Chain!Y179),ABS(Chain!Y182),ABS(Chain!Y185),ABS(Chain!Y188),ABS(Chain!Y191),ABS(Chain!Y194),ABS(Chain!Y197),ABS(Chain!Y200),ABS(Chain!Y203),ABS(Chain!Y206),ABS(Chain!Y209),ABS(Chain!Y212),ABS(Chain!Y215),ABS(Chain!Y218),ABS(Chain!Y221),ABS(Chain!Y224),ABS(Chain!Y227),ABS(Chain!Y230),ABS(Chain!Y233),ABS(Chain!Y236),ABS(Chain!Y239),ABS(Chain!Y242),ABS(Chain!Y245),ABS(Chain!Y248),ABS(Chain!Y251),ABS(Chain!Y254),ABS(Chain!Y257),ABS(Chain!Y263),ABS(Chain!Y266),ABS(Chain!Y269),ABS(Chain!Y272),ABS(Chain!Y275),ABS(Chain!Y278),ABS(Chain!Y281),ABS(Chain!Y284),ABS(Chain!Y287),ABS(Chain!Y290),ABS(Chain!Y293),ABS(Chain!Y296),ABS(Chain!Y299),ABS(Chain!Y302),ABS(Chain!Y305),ABS(Chain!Y308),ABS(Chain!Y311),ABS(Chain!Y314),ABS(Chain!Y317),ABS(Chain!Y320),ABS(Chain!Y323),ABS(Chain!Y326),ABS(Chain!Y329),ABS(Chain!Y332),ABS(Chain!Y335),ABS(Chain!Y338),ABS(Chain!Y341),ABS(Chain!Y344),ABS(Chain!Y347)) -> 1.4210855e-14 | E37: Triangle 86 excluded: its printed excesses add to 2.48″ against a total of 3.48″ (Source notes).

Sheet Curvature from angles
A1: Radius of curvature from the triangles alone (Theorema Egregium)
A2: Each triangle’s observed angles (Tome I, “angles observés”) add up to 180° + excess, and excess = area / R². Areas come from the measured distances (the chain scaled by the Melun base). No astronomy is used. Only triangles in which all three angles were observed are included.
A4: Triangle | B4: Area (km²) | C4: Observed sum − 180° (″) | D4: Excess (radians) | E4: Expected at fitted R (″) | F4: Residual (″) | H4: Triangles used | I4: =COUNT(A5:A95) -> 91
A5: 1 | B5: 234.593 | C5: 0 | D5: =C5*PI()/180/3600 -> 0 | E5: =B5*1000000/($I$6*1000)^2*180/PI()*3600 -> 1.6827096 | F5: =C5-E5 -> -1.6827096 | H5: Curvature K = Σ(A·ε)/Σ(A²) (1/m²) | I5: =SUMPRODUCT(B5:B95,D5:D95)/1000000/SUMSQ(B5:B95) -> 3.4775149e-14
A6: 3 | B6: 330.635 | C6: 0.77 | D6: =C6*PI()/180/3600 -> 3.7330653e-06 | E6: =B6*1000000/($I$6*1000)^2*180/PI()*3600 -> 2.3716083 | F6: =C6-E6 -> -1.6016083 | H6: Radius R = 1/√K (km) | I6: =1/SQRT(I5)/1000 -> 5362.4777
A7: 6 | B7: 358.939 | C7: 0.72 | D7: =C7*PI()/180/3600 -> 3.4906585e-06 | E7: =B7*1000000/($I$6*1000)^2*180/PI()*3600 -> 2.5746297 | F7: =C7-E7 -> -1.8546297 | H7: Scatter of one triangle’s closure (″) | I7: =SQRT(SUMSQ(F5:F95)/(I4-1)) -> 1.8026566
A8: 11 | B8: 245.759 | C8: 0 | D8: =C8*PI()/180/3600 -> 0 | E8: =B8*1000000/($I$6*1000)^2*180/PI()*3600 -> 1.7628021 | F8: =C8-E8 -> -1.7628021 | H8: 1-σ range of R, low (km) | I8: =1/SQRT(I5+I7*PI()/648000/SQRT(SUMSQ(B5:B95))/1000000)/1000 -> 5156.9806
A9: 12 | B9: 288.517 | C9: 3.62 | D9: =C9*PI()/180/3600 -> 1.7550255e-05 | E9: =B9*1000000/($I$6*1000)^2*180/PI()*3600 -> 2.0695005 | F9: =C9-E9 -> 1.5504995 | H9: 1-σ range of R, high (km) | I9: =1/SQRT(I5-I7*PI()/648000/SQRT(SUMSQ(B5:B95))/1000000)/1000 -> 5594.6767
A10: 13 | B10: 159.356 | C10: -1.32 | D10: =C10*PI()/180/3600 -> -6.3995406e-06 | E10: =B10*1000000/($I$6*1000)^2*180/PI()*3600 -> 1.1430429 | F10: =C10-E10 -> -2.4630429 | H10: Modern mean Earth radius (km) | I10: 6371
A11: 14 | B11: 114.659 | C11: 2.74 | D11: =C11*PI()/180/3600 -> 1.3283895e-05 | E11: =B11*1000000/($I$6*1000)^2*180/PI()*3600 -> 0.82243631 | F11: =C11-E11 -> 1.9175637 | H11: Mean observed excess (″) | I11: =AVERAGE(C5:C95) -> 2.1073626
A12: 17 | B12: 270.131 | C12: 1.34 | D12: =C12*PI()/180/3600 -> 6.4965033e-06 | E12: =B12*1000000/($I$6*1000)^2*180/PI()*3600 -> 1.9376198 | F12: =C12-E12 -> -0.59761976 | H12: Mean excess expected at 6 371 km (″) | I12: =AVERAGE(B5:B95)*1000000/(I10*1000)^2*648000/PI() -> 1.4453516
A13: 18 | B13: 141.452 | C13: 0.9 | D13: =C13*PI()/180/3600 -> 4.3633231e-06 | E13: =B13*1000000/($I$6*1000)^2*180/PI()*3600 -> 1.0146195 | F13: =C13-E13 -> -0.11461954
A14: 19 | B14: 181.063 | C14: -1.44 | D14: =C14*PI()/180/3600 -> -6.981317e-06 | E14: =B14*1000000/($I$6*1000)^2*180/PI()*3600 -> 1.2987449 | F14: =C14-E14 -> -2.7387449 | H14: Why it comes out low: the observed excesses average about 0.66″ more than a 6 371 km sphere predicts, a systematic error of roughly 0.2″ per measured angle (lateral refraction, signal phase, centring). Fitting a constant bias per triangle as well gives 0.29″ of bias and R ≈ 5 700 km (1-σ 5 200–6 300 km).
A15: 20 | B15: 95.607 | C15: 5.18 | D15: =C15*PI()/180/3600 -> 2.5113349e-05 | E15: =B15*1000000/($I$6*1000)^2*180/PI()*3600 -> 0.68577843 | F15: =C15-E15 -> 4.4942216
A16: 21 | B16: 50.979 | C16: 3.92 | D16: =C16*PI()/180/3600 -> 1.9004696e-05 | E16: =B16*1000000/($I$6*1000)^2*180/PI()*3600 -> 0.36566672 | F16: =C16-E16 -> 3.5543333
A17: 23 | B17: 89.787 | C17: -3 | D17: =C17*PI()/180/3600 -> -1.454441e-05 | E17: =B17*1000000/($I$6*1000)^2*180/PI()*3600 -> 0.64403221 | F17: =C17-E17 -> -3.6440322
A18: 24 | B18: 178.63 | C18: -0.23 | D18: =C18*PI()/180/3600 -> -1.1150715e-06 | E18: =B18*1000000/($I$6*1000)^2*180/PI()*3600 -> 1.2812932 | F18: =C18-E18 -> -1.5112932
A19: 25 | B19: 185.728 | C19: -1 | D19: =C19*PI()/180/3600 -> -4.8481368e-06 | E19: =B19*1000000/($I$6*1000)^2*180/PI()*3600 -> 1.3322064 | F19: =C19-E19 -> -2.3322064
A20: 26 | B20: 204.956 | C20: 3.99 | D20: =C20*PI()/180/3600 -> 1.9344066e-05 | E20: =B20*1000000/($I$6*1000)^2*180/PI()*3600 -> 1.4701267 | F20: =C20-E20 -> 2.5198733
A21: 27 | B21: 211.267 | C21: 2.16 | D21: =C21*PI()/180/3600 -> 1.0471976e-05 | E21: =B21*1000000/($I$6*1000)^2*180/PI()*3600 -> 1.5153948 | F21: =C21-E21 -> 0.6446052
A22: 28 | B22: 160.709 | C22: 1.4 | D22: =C22*PI()/180/3600 -> 6.7873915e-06 | E22: =B22*1000000/($I$6*1000)^2*180/PI()*3600 -> 1.1527479 | F22: =C22-E22 -> 0.24725213
A23: 29 | B23: 192.99 | C23: 2.17 | D23: =C23*PI()/180/3600 -> 1.0520457e-05 | E23: =B23*1000000/($I$6*1000)^2*180/PI()*3600 -> 1.3842959 | F23: =C23-E23 -> 0.7857041
A24: 30 | B24: 231.753 | C24: 4.88 | D24: =C24*PI()/180/3600 -> 2.3658908e-05 | E24: =B24*1000000/($I$6*1000)^2*180/PI()*3600 -> 1.6623386 | F24: =C24-E24 -> 3.2176614
A25: 31 | B25: 261.857 | C25: 2.57 | D25: =C25*PI()/180/3600 -> 1.2459712e-05 | E25: =B25*1000000/($I$6*1000)^2*180/PI()*3600 -> 1.8782713 | F25: =C25-E25 -> 0.69172873
A26: 32 | B26: 384.431 | C26: 3.04 | D26: =C26*PI()/180/3600 -> 1.4738336e-05 | E26: =B26*1000000/($I$6*1000)^2*180/PI()*3600 -> 2.757481 | F26: =C26-E26 -> 0.282519
... A95: 115 | B95: 81.441 | C95: 2.37 | D95: =C95*PI()/180/3600 -> 1.1490084e-05 | E95: =B95*1000000/($I$6*1000)^2*180/PI()*3600 -> 0.58416728 | F95: =C95-E95 -> 1.7858327

Sheet Chain
A1: Chaîne des triangles, Dunkerque → Barcelone (Tableau complet, Tome II pp. 800–839)
A2: Blue = transcribed from the scan; black = formula. Each side is carried from its base by the sine rule on the sphere (log sin side = log sin base + log sin opposite angle − log sin base angle), exactly as Delambre did. Column S repeats the chain with the original Tome I angles.
A4: No | B4: Angle at | C4: Opposite side | D4: Deg | E4: Min | F4: Sec (Tome II) | G4: Excess (″) | H4: log sin angle (printed) | I4: log sin angle (used) | J4: log sin angle from angle | K4: angle−log check (×1e-10) | L4: Role | M4: Base taken from triangle | N4: log sin side (printed) | O4: log sin side — chain, Tome II | P4: chain − printed (×1e-10) | Q4: Δ Tome II − Tome I (″) | R4: log sin angle, Tome I | S4: log sin side — chain, Tome I | T4: log sin side — chain, angles recomputed | U4: Arc (toises), from chain | V4: Arc (toises), printed | W4: printed − chain (mm) | X4: Arc (metres) | Y4: Angle sum − 180° − excess (″)
A5: 1 | B5: Dunkerque | C5: Watten – Cassel | D5: 42 | E5: 6 | F5: 9.73 | G5: 0.34 | H5: 9.8263739 | I5: =H5 -> 9.8263739 | J5: =10+LOG10(SIN(RADIANS(D5+E5/60+F5/3600))) -> 9.8263739 | K5: =(I5-J5)*10000000000 -> 1.8120083 | L5: seed | N5: 3.9913641 | O5: =N5 -> 3.9913641 | P5: =IF(N5="","",(O5-N5)*10000000000) -> 0 | Q5: 0 | R5: =I5-COS(RADIANS(D5+E5/60+F5/3600))/SIN(RADIANS(D5+E5/60+F5/3600))*RADIANS(Q5/3600)/LN(10) -> 9.8263739 | S5: =N5 -> 3.9913641 | T5: =N5 -> 3.9913641 | U5: =Summary!$C$6*ASIN(10^O5/Summary!$C$6) -> 9803.1307 | V5: 9803.1307 | W5: =IF(V5="","",(V5-U5)*Summary!$C$7*1000) -> -0.023139657 | X5: =U5*Summary!$C$7 -> 19106.66 | Y5: =(D5+D6+D7-180)*3600+(E5+E6+E7)*60+F5+F6+F7-(G5+G6+G7) -> 4.8849813e-15
A6: 1 | B6: Watten | C6: Dunkerque – Cassel | D6: 74 | E6: 28 | F6: 45.28 | G6: 0.45 | H6: 9.9838669 | I6: =H6 -> 9.9838669 | J6: =10+LOG10(SIN(RADIANS(D6+E6/60+F6/3600))) -> 9.9838669 | K6: =(I6-J6)*10000000000 -> -0.66927797 | L6: seed | N6: 4.1488571 | O6: =N6 -> 4.1488571 | P6: =IF(N6="","",(O6-N6)*10000000000) -> 0 | Q6: 0 | R6: =I6-COS(RADIANS(D6+E6/60+F6/3600))/SIN(RADIANS(D6+E6/60+F6/3600))*RADIANS(Q6/3600)/LN(10) -> 9.9838669 | S6: =N6 -> 4.1488571 | T6: =N6 -> 4.1488571 | U6: =Summary!$C$6*ASIN(10^O6/Summary!$C$6) -> 14088.295 | V6: 14088.294 | W6: =IF(V6="","",(V6-U6)*Summary!$C$7*1000) -> -0.020454007 | X6: =U6*Summary!$C$7 -> 27458.602
A7: 1 | B7: Cassel | C7: Dunkerque – Watten | D7: 63 | E7: 25 | F7: 6.17 | G7: 0.39 | H7: 9.9514822 | I7: =H7 -> 9.9514822 | J7: =10+LOG10(SIN(RADIANS(D7+E7/60+F7/3600))) -> 9.9514822 | K7: =(I7-J7)*10000000000 -> -2.5148061 | L7: seed | N7: 4.1164724 | O7: =N7 -> 4.1164724 | P7: =IF(N7="","",(O7-N7)*10000000000) -> 0 | Q7: 0 | R7: =I7-COS(RADIANS(D7+E7/60+F7/3600))/SIN(RADIANS(D7+E7/60+F7/3600))*RADIANS(Q7/3600)/LN(10) -> 9.9514822 | S7: =N7 -> 4.1164724 | T7: =N7 -> 4.1164724 | U7: =Summary!$C$6*ASIN(10^O7/Summary!$C$6) -> 13075.959 | V7: 13075.959 | W7: =IF(V7="","",(V7-U7)*Summary!$C$7*1000) -> 0.15295599 | X7: =U7*Summary!$C$7 -> 25485.523
A8: 2 | B8: Dunkerque | C8: Watten – Gravelines | D8: 46 | E8: 52 | F8: 0.32 | G8: 0.21 | H8: 9.8631834 | I8: =H8 -> 9.8631834 | J8: =10+LOG10(SIN(RADIANS(D8+E8/60+F8/3600))) -> 9.8631834 | K8: =(I8-J8)*10000000000 -> 0.20623503 | L8: computed | N8: 3.9800462 | O8: =O10+I8-I10 -> 3.9800462 | P8: =IF(N8="","",(O8-N8)*10000000000) -> 0 | Q8: 0 | R8: =I8-COS(RADIANS(D8+E8/60+F8/3600))/SIN(RADIANS(D8+E8/60+F8/3600))*RADIANS(Q8/3600)/LN(10) -> 9.8631834 | S8: =S10+R8-R10 -> 3.9800462 | T8: =T10+J8-J10 -> 3.9800462 | U8: =Summary!$C$6*ASIN(10^O8/Summary!$C$6) -> 9550.9556 | V8: 9550.9556 | W8: =IF(V8="","",(V8-U8)*Summary!$C$7*1000) -> 0.06081646 | X8: =U8*Summary!$C$7 -> 18615.162 | Y8: =(D8+D9+D10-180)*3600+(E8+E9+E10)*60+F8+F9+F10-(G8+G9+G10) -> 0
A9: 2 | B9: Watten | C9: Dunkerque – Gravelines | D9: 45 | E9: 33 | F9: 44.65 | G9: 0.23 | H9: 9.8537064 | I9: =H9 -> 9.8537064 | J9: =10+LOG10(SIN(RADIANS(D9+E9/60+F9/3600))) -> 9.8537064 | K9: =(I9-J9)*10000000000 -> -3.2800251 | L9: computed | N9: 3.9705691 | O9: =O10+I9-I10 -> 3.9705691 | P9: =IF(N9="","",(O9-N9)*10000000000) -> 0 | Q9: 0 | R9: =I9-COS(RADIANS(D9+E9/60+F9/3600))/SIN(RADIANS(D9+E9/60+F9/3600))*RADIANS(Q9/3600)/LN(10) -> 9.8537064 | S9: =S10+R9-R10 -> 3.9705691 | T9: =T10+J9-J10 -> 3.9705691 | U9: =Summary!$C$6*ASIN(10^O9/Summary!$C$6) -> 9344.7937 | V9: 9344.7937 | W9: =IF(V9="","",(V9-U9)*Summary!$C$7*1000) -> -0.019790516 | X9: =U9*Summary!$C$7 -> 18213.345
A10: 2 | B10: Gravelines | C10: Dunkerque – Watten | D10: 87 | E10: 34 | F10: 15.89 | G10: 0.42 | H10: 9.9996096 | I10: =H10 -> 9.9996096 | J10: =10+LOG10(SIN(RADIANS(D10+E10/60+F10/3600))) -> 9.9996096 | K10: =(I10-J10)*10000000000 -> -2.2037305 | L10: base | M10: 1 | O10: =O7 -> 4.1164724 | Q10: 0 | R10: =I10-COS(RADIANS(D10+E10/60+F10/3600))/SIN(RADIANS(D10+E10/60+F10/3600))*RADIANS(Q10/3600)/LN(10) -> 9.9996096 | S10: =S7 -> 4.1164724 | T10: =T7 -> 4.1164724
A11: 3 | B11: Watten | C11: Cassel – Fiefs | D11: 69 | E11: 34 | F11: 45.38 | G11: 0.54 | H11: 9.9718118 | I11: =H11 -> 9.9718118 | J11: =10+LOG10(SIN(RADIANS(D11+E11/60+F11/3600))) -> 9.9718118 | K11: =(I11-J11)*10000000000 -> -1.8042989 | L11: computed | N11: 4.2562771 | O11: =O13+I11-I13 -> 4.2562771 | P11: =IF(N11="","",(O11-N11)*10000000000) -> -0.9999912 | Q11: 0 | R11: =I11-COS(RADIANS(D11+E11/60+F11/3600))/SIN(RADIANS(D11+E11/60+F11/3600))*RADIANS(Q11/3600)/LN(10) -> 9.9718118 | S11: =S13+R11-R13 -> 4.2562771 | T11: =T13+J11-J13 -> 4.2562771 | U11: =Summary!$C$6*ASIN(10^O11/Summary!$C$6) -> 18041.777 | V11: 18041.777 | W11: =IF(V11="","",(V11-U11)*Summary!$C$7*1000) -> 0.049674413 | X11: =U11*Summary!$C$7 -> 35164.084 | Y11: =(D11+D12+D13-180)*3600+(E11+E12+E13)*60+F11+F12+F13-(G11+G12+G13) -> 0
A12: 3 | B12: Cassel | C12: Watten – Fiefs | D12: 79 | E12: 48 | F12: 35.35 | G12: 0.68 | H12: 9.9930948 | I12: =H12 -> 9.9930948 | J12: =10+LOG10(SIN(RADIANS(D12+E12/60+F12/3600))) -> 9.9930948 | K12: =(I12-J12)*10000000000 -> -2.4196645 | L12: computed | N12: 4.2775601 | O12: =O13+I12-I13 -> 4.2775601 | P12: =IF(N12="","",(O12-N12)*10000000000) -> -0.9999912 | Q12: 0 | R12: =I12-COS(RADIANS(D12+E12/60+F12/3600))/SIN(RADIANS(D12+E12/60+F12/3600))*RADIANS(Q12/3600)/LN(10) -> 9.9930948 | S12: =S13+R12-R13 -> 4.2775601 | T12: =T13+J12-J13 -> 4.2775601 | U12: =Summary!$C$6*ASIN(10^O12/Summary!$C$6) -> 18947.964 | V12: 18947.964 | W12: =IF(V12="","",(V12-U12)*Summary!$C$7*1000) -> 0.074099152 | X12: =U12*Summary!$C$7 -> 36930.275
A13: 3 | B13: Fiefs | C13: Watten – Cassel | D13: 30 | E13: 36 | F13: 40.94 | G13: 0.45 | H13: 9.7068988 | I13: =H13 -> 9.7068988 | J13: =10+LOG10(SIN(RADIANS(D13+E13/60+F13/3600))) -> 9.7068988 | K13: =(I13-J13)*10000000000 -> -0.43376858 | L13: base | M13: 1 | O13: =O5 -> 3.9913641 | Q13: 0 | R13: =I13-COS(RADIANS(D13+E13/60+F13/3600))/SIN(RADIANS(D13+E13/60+F13/3600))*RADIANS(Q13/3600)/LN(10) -> 9.7068988 | S13: =S5 -> 3.9913641 | T13: =T5 -> 3.9913641
A14: 4 | B14: Watten | C14: Cassel – Helfaut | D14: 74 | E14: 39 | F14: 23.2 | G14: 0.28 | H14: 9.9842376 | I14: =H14 -> 9.9842376 | J14: =10+LOG10(SIN(RADIANS(D14+E14/60+F14/3600))) -> 9.9842376 | K14: =(I14-J14)*10000000000 -> -0.045154991 | L14: computed | N14: 4.0308136 | O14: =O16+I14-I16 -> 4.0308136 | P14: =IF(N14="","",(O14-N14)*10000000000) -> 0 | Q14: 0 | R14: =I14-COS(RADIANS(D14+E14/60+F14/3600))/SIN(RADIANS(D14+E14/60+F14/3600))*RADIANS(Q14/3600)/LN(10) -> 9.9842376 | S14: =S16+R14-R16 -> 4.0308136 | T14: =T16+J14-J16 -> 4.0308136 | U14: =Summary!$C$6*ASIN(10^O14/Summary!$C$6) -> 10735.304 | V14: 10735.304 | W14: =IF(V14="","",(V14-U14)*Summary!$C$7*1000) -> 0.0042676164 | X14: =U14*Summary!$C$7 -> 20923.501 | Y14: =(D14+D15+D16-180)*3600+(E14+E15+E16)*60+F14+F15+F16-(G14+G15+G16) -> 0
A15: 4 | B15: Cassel | C15: Watten – Helfaut | D15: 43 | E15: 37 | F15: 35.73 | G15: 0.21 | H15: 9.8388211 | I15: =H15 -> 9.8388211 | J15: =10+LOG10(SIN(RADIANS(D15+E15/60+F15/3600))) -> 9.8388211 | K15: =(I15-J15)*10000000000 -> -3.8373038 | L15: computed | N15: 3.8853971 | O15: =O16+I15-I16 -> 3.8853971 | P15: =IF(N15="","",(O15-N15)*10000000000) -> 1.0000045 | Q15: 0 | R15: =I15-COS(RADIANS(D15+E15/60+F15/3600))/SIN(RADIANS(D15+E15/60+F15/3600))*RADIANS(Q15/3600)/LN(10) -> 9.8388211 | S15: =S16+R15-R16 -> 3.8853971 | T15: =T16+J15-J16 -> 3.8853971 | U15: =Summary!$C$6*ASIN(10^O15/Summary!$C$6) -> 7680.6409 | V15: 7680.6409 | W15: =IF(V15="","",(V15-U15)*Summary!$C$7*1000) -> 0.05711958 | X15: =U15*Summary!$C$7 -> 14969.85
A16: 4 | B16: Helfaut | C16: Watten – Cassel | D16: 61 | E16: 43 | F16: 1.78 | G16: 0.22 | H16: 9.9447882 | I16: =H16 -> 9.9447882 | J16: =10+LOG10(SIN(RADIANS(D16+E16/60+F16/3600))) -> 9.9447882 | K16: =(I16-J16)*10000000000 -> -0.72578388 | L16: base | M16: 1 | O16: =O5 -> 3.9913641 | Q16: 0 | R16: =I16-COS(RADIANS(D16+E16/60+F16/3600))/SIN(RADIANS(D16+E16/60+F16/3600))*RADIANS(Q16/3600)/LN(10) -> 9.9447882 | S16: =S5 -> 3.9913641 | T16: =T5 -> 3.9913641
A17: 5 | B17: Cassel | C17: Fiefs – Helfaut | D17: 36 | E17: 10 | F17: 59 | G17: 0.11 | H17: 9.7711221 | I17: =H17 -> 9.7711221 | J17: =10+LOG10(SIN(RADIANS(D17+E17/60+F17/3600))) -> 9.7711221 | K17: =(I17-J17)*10000000000 -> -1.5537793 | L17: computed | N17: 4.0537636 | O17: =O19+I17-I19 -> 4.0537636 | P17: =IF(N17="","",(O17-N17)*10000000000) -> -0.99998232 | Q17: 0 | R17: =I17-COS(RADIANS(D17+E17/60+F17/3600))/SIN(RADIANS(D17+E17/60+F17/3600))*RADIANS(Q17/3600)/LN(10) -> 9.7711221 | S17: =S19+R17-R19 -> 4.0537636 | T17: =T19+J17-J19 -> 4.0537636 | U17: =Summary!$C$6*ASIN(10^O17/Summary!$C$6) -> 11317.864 | V17: 11317.864 | W17: =IF(V17="","",(V17-U17)*Summary!$C$7*1000) -> 0.0076778502 | X17: =U17*Summary!$C$7 -> 22058.931 | Y17: =(D17+D18+D19-180)*3600+(E17+E18+E19)*60+F17+F18+F19-(G17+G18+G19) -> 0
A18: 5 | B18: Fiefs | C18: Cassel – Helfaut | D18: 34 | E18: 3 | F18: 15.47 | G18: 0.12 | H18: 9.7481712 | I18: =H18 -> 9.7481712 | J18: =10+LOG10(SIN(RADIANS(D18+E18/60+F18/3600))) -> 9.7481712 | K18: =(I18-J18)*10000000000 -> -4.2879478 | L18: computed | N18: 4.0308127 | O18: =O19+I18-I19 -> 4.0308127 | P18: =IF(N18="","",(O18-N18)*10000000000) -> -0.9999912 | Q18: 0 | R18: =I18-COS(RADIANS(D18+E18/60+F18/3600))/SIN(RADIANS(D18+E18/60+F18/3600))*RADIANS(Q18/3600)/LN(10) -> 9.7481712 | S18: =S19+R18-R19 -> 4.0308127 | T18: =T19+J18-J19 -> 4.0308127 | U18: =Summary!$C$6*ASIN(10^O18/Summary!$C$6) -> 10735.283 | V18: 10735.283 | W18: =IF(V18="","",(V18-U18)*Summary!$C$7*1000) -> -0.0033174432 | X18: =U18*Summary!$C$7 -> 20923.46
A19: 5 | B19: Helfaut | C19: Cassel – Fiefs | D19: 109 | E19: 45 | F19: 46.64 | G19: 0.88 | H19: 9.9736356 | I19: =H19 -> 9.9736356 | J19: =10+LOG10(SIN(RADIANS(D19+E19/60+F19/3600))) -> 9.9736356 | K19: =(I19-J19)*10000000000 -> -1.2727774 | L19: base | M19: 3 | O19: =O11 -> 4.2562771 | Q19: 0 | R19: =I19-COS(RADIANS(D19+E19/60+F19/3600))/SIN(RADIANS(D19+E19/60+F19/3600))*RADIANS(Q19/3600)/LN(10) -> 9.9736356 | S19: =S11 -> 4.2562771 | T19: =T11 -> 4.2562771
A20: 6 | B20: Cassel | C20: Fiefs – Mesnil | D20: 29 | E20: 50 | F20: 27.95 | G20: 0.41 | H20: 9.6968771 | I20: =H20 -> 9.6968771 | J20: =10+LOG10(SIN(RADIANS(D20+E20/60+F20/3600))) -> 9.6968771 | K20: =(I20-J20)*10000000000 -> -3.0741276 | L20: computed | N20: 4.0202222 | O20: =O22+I20-I22 -> 4.0202222 | P20: =IF(N20="","",(O20-N20)*10000000000) -> -0.9999912 | Q20: 0 | R20: =I20-COS(RADIANS(D20+E20/60+F20/3600))/SIN(RADIANS(D20+E20/60+F20/3600))*RADIANS(Q20/3600)/LN(10) -> 9.6968771 | S20: =S22+R20-R22 -> 4.0202222 | T20: =T22+J20-J22 -> 4.0202222 | U20: =Summary!$C$6*ASIN(10^O20/Summary!$C$6) -> 10476.663 | V20: 10476.663 | W20: =IF(V20="","",(V20-U20)*Summary!$C$7*1000) -> 0.015915712 | X20: =U20*Summary!$C$7 -> 20419.4 | Y20: =(D20+D21+D22-180)*3600+(E20+E21+E22)*60+F20+F21+F22-(G20+G21+G22) -> 0
A21: 6 | B21: Fiefs | C21: Cassel – Mesnil | D21: 91 | E21: 11 | F21: 19.4 | G21: 0.93 | H21: 9.9999065 | I21: =H21 -> 9.9999065 | J21: =10+LOG10(SIN(RADIANS(D21+E21/60+F21/3600))) -> 9.9999065 | K21: =(I21-J21)*10000000000 -> -0.16401103 | L21: computed | N21: 4.3232516 | O21: =O22+I21-I22 -> 4.3232516 | P21: =IF(N21="","",(O21-N21)*10000000000) -> -0.9999912 | Q21: 0 | R21: =I21-COS(RADIANS(D21+E21/60+F21/3600))/SIN(RADIANS(D21+E21/60+F21/3600))*RADIANS(Q21/3600)/LN(10) -> 9.9999065 | S21: =S22+R21-R22 -> 4.3232516 | T21: =T22+J21-J22 -> 4.3232516 | U21: =Summary!$C$6*ASIN(10^O21/Summary!$C$6) -> 21050.124 | V21: 21050.124 | W21: =IF(V21="","",(V21-U21)*Summary!$C$7*1000) -> -0.032079537 | X21: =U21*Summary!$C$7 -> 41027.462
A22: 6 | B22: Mesnil | C22: Cassel – Fiefs | D22: 58 | E22: 58 | F22: 14.45 | G22: 0.46 | H22: 9.932932 | I22: =H22 -> 9.932932 | J22: =10+LOG10(SIN(RADIANS(D22+E22/60+F22/3600))) -> 9.932932 | K22: =(I22-J22)*10000000000 -> -1.8863311 | L22: base | M22: 3 | O22: =O11 -> 4.2562771 | Q22: 0 | R22: =I22-COS(RADIANS(D22+E22/60+F22/3600))/SIN(RADIANS(D22+E22/60+F22/3600))*RADIANS(Q22/3600)/LN(10) -> 9.932932 | S22: =S11 -> 4.2562771 | T22: =T11 -> 4.2562771
A23: 7 | B23: Cassel | C23: Béthune – Fiefs | D23: 39 | E23: 42 | F23: 10.51 | G23: 0.51 | H23: 9.8053697 | I23: =H23 -> 9.8053697 | J23: =10+LOG10(SIN(RADIANS(D23+E23/60+F23/3600))) -> 9.8053697 | K23: =(I23-J23)*10000000000 -> -0.69901418 | L23: computed | N23: 4.0702055 | O23: =O24+I23-I24 -> 4.0702055 | P23: =IF(N23="","",(O23-N23)*10000000000) -> -1.0000001 | Q23: 0 | R23: =I23-COS(RADIANS(D23+E23/60+F23/3600))/SIN(RADIANS(D23+E23/60+F23/3600))*RADIANS(Q23/3600)/LN(10) -> 9.8053697 | S23: =S24+R23-R24 -> 4.0702055 | T23: =T24+J23-J24 -> 4.0702055 | U23: =Summary!$C$6*ASIN(10^O23/Summary!$C$6) -> 11754.561 | V23: 11754.561 | W23: =IF(V23="","",(V23-U23)*Summary!$C$7*1000) -> -0.018000598 | X23: =U23*Summary!$C$7 -> 22910.07 | Y23: =(D23+D24+D25-180)*3600+(E23+E24+E25)*60+F23+F24+F25-(G23+G24+G25) -> 0
A24: 7 | B24: Béthune | C24: Cassel – Fiefs | D24: 78 | E24: 39 | F24: 44.58 | G24: 0.73 | H24: 9.9914413 | I24: =H24 -> 9.9914413 | J24: =10+LOG10(SIN(RADIANS(D24+E24/60+F24/3600))) -> 9.9914413 | K24: =(I24-J24)*10000000000 -> -1.1478996 | L24: base | M24: 3 | O24: =O11 -> 4.2562771 | Q24: 0 | R24: =I24-COS(RADIANS(D24+E24/60+F24/3600))/SIN(RADIANS(D24+E24/60+F24/3600))*RADIANS(Q24/3600)/LN(10) -> 9.9914413 | S24: =S11 -> 4.2562771 | T24: =T11 -> 4.2562771
A25: 7 | B25: Fiefs | C25: Cassel – Béthune | D25: 61 | E25: 38 | F25: 6.71 | G25: 0.56 | H25: 9.9444533 | I25: =H25 -> 9.9444533 | J25: =10+LOG10(SIN(RADIANS(D25+E25/60+F25/3600))) -> 9.9444533 | K25: =(I25-J25)*10000000000 -> -2.4562929 | L25: computed | N25: 4.2092892 | O25: =O24+I25-I24 -> 4.2092892 | P25: =IF(N25="","",(O25-N25)*10000000000) -> -1.0000001 | Q25: 0 | R25: =I25-COS(RADIANS(D25+E25/60+F25/3600))/SIN(RADIANS(D25+E25/60+F25/3600))*RADIANS(Q25/3600)/LN(10) -> 9.9444533 | S25: =S24+R25-R24 -> 4.2092892 | T25: =T24+J25-J24 -> 4.2092892 | U25: =Summary!$C$6*ASIN(10^O25/Summary!$C$6) -> 16191.643 | V25: 16191.643 | W25: =IF(V25="","",(V25-U25)*Summary!$C$7*1000) -> -0.0090915471 | X25: =U25*Summary!$C$7 -> 31558.105
A26: 8 | B26: Béthune | C26: Mesnil – Fiefs | D26: 62 | E26: 55 | F26: 40.04 | G26: 0.16 | H26: 9.9496016 | I26: =H26 -> 9.9496016 | J26: =10+LOG10(SIN(RADIANS(D26+E26/60+F26/3600))) -> 9.9496016 | K26: =(I26-J26)*10000000000 -> -1.8746071 | L26: base | M26: 6 | O26: =O20 -> 4.0202222 | Q26: 0 | R26: =I26-COS(RADIANS(D26+E26/60+F26/3600))/SIN(RADIANS(D26+E26/60+F26/3600))*RADIANS(Q26/3600)/LN(10) -> 9.9496016 | S26: =S20 -> 4.0202222 | T26: =T20 -> 4.0202222 | Y26: =(D26+D27+D28-180)*3600+(E26+E27+E28)*60+F26+F27+F28-(G26+G27+G28) -> 0
A27: 8 | B27: Mesnil | C27: Béthune – Fiefs | D27: 87 | E27: 31 | F27: 2.11 | G27: 0.27 | H27: 9.9995921 | I27: =H27 -> 9.9995921 | J27: =10+LOG10(SIN(RADIANS(D27+E27/60+F27/3600))) -> 9.9995921 | K27: =(I27-J27)*10000000000 -> -1.3071144 | L27: computed | N27: 4.0702128 | O27: =O26+I27-I26 -> 4.0702128 | P27: =IF(N27="","",(O27-N27)*10000000000) -> -0.99998232 | Q27: 0 | R27: =I27-COS(RADIANS(D27+E27/60+F27/3600))/SIN(RADIANS(D27+E27/60+F27/3600))*RADIANS(Q27/3600)/LN(10) -> 9.9995921 | S27: =S26+R27-R26 -> 4.0702128 | T27: =T26+J27-J26 -> 4.0702128 | U27: =Summary!$C$6*ASIN(10^O27/Summary!$C$6) -> 11754.76 | V27: 11754.76 | W27: =IF(V27="","",(V27-U27)*Summary!$C$7*1000) -> -0.02017415 | X27: =U27*Summary!$C$7 -> 22910.457
A28: 8 | B28: Fiefs | C28: Béthune – Mesnil | D28: 29 | E28: 33 | F28: 18.44 | G28: 0.16 | H28: 9.6930765 | I28: =H28 -> 9.6930765 | J28: =10+LOG10(SIN(RADIANS(D28+E28/60+F28/3600))) -> 9.6930765 | K28: =(I28-J28)*10000000000 -> -3.7530867 | L28: computed | N28: 3.7636972 | O28: =O26+I28-I26 -> 3.7636972 | P28: =IF(N28="","",(O28-N28)*10000000000) -> 0 | Q28: 0 | R28: =I28-COS(RADIANS(D28+E28/60+F28/3600))/SIN(RADIANS(D28+E28/60+F28/3600))*RADIANS(Q28/3600)/LN(10) -> 9.6930765 | S28: =S26+R28-R26 -> 3.7636972 | T28: =T26+J28-J26 -> 3.7636972 | U28: =Summary!$C$6*ASIN(10^O28/Summary!$C$6) -> 5803.599 | V28: 5803.599 | W28: =IF(V28="","",(V28-U28)*Summary!$C$7*1000) -> 0.06989966 | X28: =U28*Summary!$C$7 -> 11311.427
A29: 9 | B29: Cassel | C29: Béthune – Helfaut | D29: 75 | E29: 53 | F29: 9.51 | G29: 0.64 | H29: 9.9866877 | I29: =H29 -> 9.9866877 | J29: =10+LOG10(SIN(RADIANS(D29+E29/60+F29/3600))) -> 9.9866877 | K29: =(I29-J29)*10000000000 -> 0.040891734 | L29: computed | N29: 4.2331671 | O29: =O30+I29-I30 -> 4.2331671 | P29: =IF(N29="","",(O29-N29)*10000000000) -> 0 | Q29: 0 | R29: =I29-COS(RADIANS(D29+E29/60+F29/3600))/SIN(RADIANS(D29+E29/60+F29/3600))*RADIANS(Q29/3600)/LN(10) -> 9.9866877 | S29: =S30+R29-R30 -> 4.2331671 | T29: =T30+J29-J30 -> 4.2331671 | U29: =Summary!$C$6*ASIN(10^O29/Summary!$C$6) -> 17106.811 | V29: 17106.811 | W29: =IF(V29="","",(V29-U29)*Summary!$C$7*1000) -> 0.085266753 | X29: =U29*Summary!$C$7 -> 33341.8 | Y29: =(D29+D30+D31-180)*3600+(E29+E30+E31)*60+F29+F30+F31-(G29+G30+G31) -> 0
A30: 9 | B30: Béthune | C30: Cassel – Helfaut | D30: 37 | E30: 29 | F30: 18.86 | G30: 0.45 | H30: 9.7843342 | I30: =H30 -> 9.7843342 | J30: =10+LOG10(SIN(RADIANS(D30+E30/60+F30/3600))) -> 9.7843342 | K30: =(I30-J30)*10000000000 -> -1.6098234 | L30: base | M30: 4 | O30: =O14 -> 4.0308136 | Q30: 0 | R30: =I30-COS(RADIANS(D30+E30/60+F30/3600))/SIN(RADIANS(D30+E30/60+F30/3600))*RADIANS(Q30/3600)/LN(10) -> 9.7843342 | S30: =S14 -> 4.0308136 | T30: =T14 -> 4.0308136
A31: 9 | B31: Helfaut | C31: Cassel – Béthune | D31: 66 | E31: 37 | F31: 33.27 | G31: 0.55 | H31: 9.9628115 | I31: =H31 -> 9.9628115 | J31: =10+LOG10(SIN(RADIANS(D31+E31/60+F31/3600))) -> 9.9628115 | K31: =(I31-J31)*10000000000 -> -0.90034646 | L31: computed | N31: 4.2092909 | O31: =O30+I31-I30 -> 4.2092909 | P31: =IF(N31="","",(O31-N31)*10000000000) -> 0 | Q31: 0 | R31: =I31-COS(RADIANS(D31+E31/60+F31/3600))/SIN(RADIANS(D31+E31/60+F31/3600))*RADIANS(Q31/3600)/LN(10) -> 9.9628115 | S31: =S30+R31-R30 -> 4.2092909 | T31: =T30+J31-J30 -> 4.2092909 | U31: =Summary!$C$6*ASIN(10^O31/Summary!$C$6) -> 16191.707 | V31: 16191.707 | W31: =IF(V31="","",(V31-U31)*Summary!$C$7*1000) -> 0.035755561 | X31: =U31*Summary!$C$7 -> 31558.23
A32: 10 | B32: Helfaut | C32: Béthune – Fiefs | D32: 43 | E32: 8 | F32: 13.37 | G32: 0.28 | H32: 9.8348946 | I32: =H32 -> 9.8348946 | J32: =10+LOG10(SIN(RADIANS(D32+E32/60+F32/3600))) -> 9.8348946 | K32: =(I32-J32)*10000000000 -> -3.0413894 | L32: computed | N32: 4.0702065 | O32: =O34+I32-I34 -> 4.0702065 | P32: =IF(N32="","",(O32-N32)*10000000000) -> 1.0000001 | Q32: 0 | R32: =I32-COS(RADIANS(D32+E32/60+F32/3600))/SIN(RADIANS(D32+E32/60+F32/3600))*RADIANS(Q32/3600)/LN(10) -> 9.8348946 | S32: =S34+R32-R34 -> 4.0702065 | T32: =T34+J32-J34 -> 4.0702065 | U32: =Summary!$C$6*ASIN(10^O32/Summary!$C$6) -> 11754.588 | V32: 11754.588 | W32: =IF(V32="","",(V32-U32)*Summary!$C$7*1000) -> 0.100126 | X32: =U32*Summary!$C$7 -> 22910.123 | Y32: =(D32+D33+D34-180)*3600+(E32+E33+E34)*60+F32+F33+F34-(G32+G33+G34) -> 0
A33: 10 | B33: Béthune | C33: Helfaut – Fiefs | D33: 41 | E33: 10 | F33: 25.44 | G33: 0.26 | H33: 9.8184532 | I33: =H33 -> 9.8184532 | J33: =10+LOG10(SIN(RADIANS(D33+E33/60+F33/3600))) -> 9.8184532 | K33: =(I33-J33)*10000000000 -> -3.2303227 | L33: computed | N33: 4.053765 | O33: =O34+I33-I34 -> 4.053765 | P33: =IF(N33="","",(O33-N33)*10000000000) -> 0 | Q33: 0 | R33: =I33-COS(RADIANS(D33+E33/60+F33/3600))/SIN(RADIANS(D33+E33/60+F33/3600))*RADIANS(Q33/3600)/LN(10) -> 9.8184532 | S33: =S34+R33-R34 -> 4.053765 | T33: =T34+J33-J34 -> 4.053765 | U33: =Summary!$C$6*ASIN(10^O33/Summary!$C$6) -> 11317.901 | V33: 11317.901 | W33: =IF(V33="","",(V33-U33)*Summary!$C$7*1000) -> 0.074854572 | X33: =U33*Summary!$C$7 -> 22059.004
A34: 10 | B34: Fiefs | C34: Helfaut – Béthune | D34: 95 | E34: 41 | F34: 22.48 | G34: 0.75 | H34: 9.9978552 | I34: =H34 -> 9.9978552 | J34: =10+LOG10(SIN(RADIANS(D34+E34/60+F34/3600))) -> 9.9978552 | K34: =(I34-J34)*10000000000 -> -1.7042012 | L34: base | M34: 9 | O34: =O29 -> 4.2331671 | Q34: 0 | R34: =I34-COS(RADIANS(D34+E34/60+F34/3600))/SIN(RADIANS(D34+E34/60+F34/3600))*RADIANS(Q34/3600)/LN(10) -> 9.9978552 | S34: =S29 -> 4.2331671 | T34: =T29 -> 4.2331671
A35: 11 | B35: Fiefs | C35: Mesnil – Sauti | D35: 42 | E35: 59 | F35: 49.63 | G35: 0.22 | H35: 9.8337599 | I35: =H35 -> 9.8337599 | J35: =10+LOG10(SIN(RADIANS(D35+E35/60+F35/3600))) -> 9.8337599 | K35: =(I35-J35)*10000000000 -> -0.22488678 | L35: computed | N35: 4.1023222 | O35: =O37+I35-I37 -> 4.1023222 | P35: =IF(N35="","",(O35-N35)*10000000000) -> 0 | Q35: 0 | R35: =I35-COS(RADIANS(D35+E35/60+F35/3600))/SIN(RADIANS(D35+E35/60+F35/3600))*RADIANS(Q35/3600)/LN(10) -> 9.8337599 | S35: =S37+R35-R37 -> 4.1023222 | T35: =T37+J35-J37 -> 4.1023222 | U35: =Summary!$C$6*ASIN(10^O35/Summary!$C$6) -> 12656.782 | V35: 12656.782 | W35: =IF(V35="","",(V35-U35)*Summary!$C$7*1000) -> 0.15249095 | X35: =U35*Summary!$C$7 -> 24668.531 | Y35: =(D35+D36+D37-180)*3600+(E35+E36+E37)*60+F35+F36+F37-(G35+G36+G37) -> 0
A36: 11 | B36: Mesnil | C36: Fiefs – Sauti | D36: 102 | E36: 38 | F36: 9.63 | G36: 0.8 | H36: 9.9893517 | I36: =H36 -> 9.9893517 | J36: =10+LOG10(SIN(RADIANS(D36+E36/60+F36/3600))) -> 9.9893517 | K36: =(I36-J36)*10000000000 -> -0.97859498 | L36: computed | N36: 4.257914 | O36: =O37+I36-I37 -> 4.257914 | P36: =IF(N36="","",(O36-N36)*10000000000) -> -0.9999912 | Q36: 0 | R36: =I36-COS(RADIANS(D36+E36/60+F36/3600))/SIN(RADIANS(D36+E36/60+F36/3600))*RADIANS(Q36/3600)/LN(10) -> 9.9893517 | S36: =S37+R36-R37 -> 4.257914 | T36: =T37+J36-J37 -> 4.257914 | U36: =Summary!$C$6*ASIN(10^O36/Summary!$C$6) -> 18109.906 | V36: 18109.906 | W36: =IF(V36="","",(V36-U36)*Summary!$C$7*1000) -> 0.092709608 | X36: =U36*Summary!$C$7 -> 35296.869
A37: 11 | B37: Sauti | C37: Fiefs – Mesnil | D37: 34 | E37: 22 | F37: 1.98 | G37: 0.22 | H37: 9.7516599 | I37: =H37 -> 9.7516599 | J37: =10+LOG10(SIN(RADIANS(D37+E37/60+F37/3600))) -> 9.7516599 | K37: =(I37-J37)*10000000000 -> -2.9060487 | L37: base | M37: 6 | O37: =O20 -> 4.0202222 | Q37: 0 | R37: =I37-COS(RADIANS(D37+E37/60+F37/3600))/SIN(RADIANS(D37+E37/60+F37/3600))*RADIANS(Q37/3600)/LN(10) -> 9.7516599 | S37: =S20 -> 4.0202222 | T37: =T20 -> 4.0202222
A38: 12 | B38: Fiefs | C38: Sauti – Bonnières | D38: 34 | E38: 32 | F38: 51.42 | G38: 0.34 | H38: 9.7536527 | I38: =H38 -> 9.7536527 | J38: =10+LOG10(SIN(RADIANS(D38+E38/60+F38/3600))) -> 9.7536527 | K38: =(I38-J38)*10000000000 -> -2.9786484 | L38: computed | N38: 4.0115991 | O38: =O40+I38-I40 -> 4.0115991 | P38: =IF(N38="","",(O38-N38)*10000000000) -> -1.9999913 | Q38: 0 | R38: =I38-COS(RADIANS(D38+E38/60+F38/3600))/SIN(RADIANS(D38+E38/60+F38/3600))*RADIANS(Q38/3600)/LN(10) -> 9.7536527 | S38: =S40+R38-R40 -> 4.0115991 | T38: =T40+J38-J40 -> 4.0115991 | U38: =Summary!$C$6*ASIN(10^O38/Summary!$C$6) -> 10270.695 | V38: 10270.695 | W38: =IF(V38="","",(V38-U38)*Summary!$C$7*1000) -> 0.077476333 | X38: =U38*Summary!$C$7 -> 20017.961 | Y38: =(D38+D39+D40-180)*3600+(E38+E39+E40)*60+F38+F39+F40-(G38+G39+G40) -> 0
A39: 12 | B39: Sauti | C39: Fiefs – Bonnières | D39: 54 | E39: 45 | F39: 8.66 | G39: 0.38 | H39: 9.9120444 | I39: =H39 -> 9.9120444 | J39: =10+LOG10(SIN(RADIANS(D39+E39/60+F39/3600))) -> 9.9120444 | K39: =(I39-J39)*10000000000 -> -1.1175949 | L39: computed | N39: 4.1699908 | O39: =O40+I39-I40 -> 4.1699908 | P39: =IF(N39="","",(O39-N39)*10000000000) -> -1.9999913 | Q39: 0 | R39: =I39-COS(RADIANS(D39+E39/60+F39/3600))/SIN(RADIANS(D39+E39/60+F39/3600))*RADIANS(Q39/3600)/LN(10) -> 9.9120444 | S39: =S40+R39-R40 -> 4.1699908 | T39: =T40+J39-J40 -> 4.1699908 | U39: =Summary!$C$6*ASIN(10^O39/Summary!$C$6) -> 14790.82 | V39: 14790.82 | W39: =IF(V39="","",(V39-U39)*Summary!$C$7*1000) -> -0.026496304 | X39: =U39*Summary!$C$7 -> 28827.85
A40: 12 | B40: Bonnières | C40: Fiefs – Sauti | D40: 90 | E40: 42 | F40: 1.39 | G40: 0.75 | H40: 9.9999676 | I40: =H40 -> 9.9999676 | J40: =10+LOG10(SIN(RADIANS(D40+E40/60+F40/3600))) -> 9.9999676 | K40: =(I40-J40)*10000000000 -> 0.21829649 | L40: base | M40: 11 | O40: =O36 -> 4.257914 | Q40: 0 | R40: =I40-COS(RADIANS(D40+E40/60+F40/3600))/SIN(RADIANS(D40+E40/60+F40/3600))*RADIANS(Q40/3600)/LN(10) -> 9.9999676 | S40: =S36 -> 4.257914 | T40: =T36 -> 4.257914
A41: 13 | B41: Bonnières | C41: Sauti – Beauquêne | D41: 51 | E41: 56 | F41: 49.41 | G41: 0.25 | H41: 9.8962183 | I41: =H41 -> 9.8962183 | J41: =10+LOG10(SIN(RADIANS(D41+E41/60+F41/3600))) -> 9.8962183 | K41: =(I41-J41)*10000000000 -> 0.65444539 | L41: computed | N41: 3.9562581 | O41: =O43+I41-I43 -> 3.9562581 | P41: =IF(N41="","",(O41-N41)*10000000000) -> -2.000009 | Q41: 0 | R41: =I41-COS(RADIANS(D41+E41/60+F41/3600))/SIN(RADIANS(D41+E41/60+F41/3600))*RADIANS(Q41/3600)/LN(10) -> 9.8962183 | S41: =S43+R41-R43 -> 3.9562581 | T41: =T43+J41-J43 -> 3.9562581 | U41: =Summary!$C$6*ASIN(10^O41/Summary!$C$6) -> 9041.8791 | V41: 9041.8792 | W41: =IF(V41="","",(V41-U41)*Summary!$C$7*1000) -> 0.21115903 | X41: =U41*Summary!$C$7 -> 17622.953 | Y41: =(D41+D42+D43-180)*3600+(E41+E42+E43)*60+F41+F42+F43-(G41+G42+G43) -> 0
...

Sheet Source notes
A1: Triangle | B1: Station | C1: Column | D1: Discrepancy in the printed source
A2: 34 | B2: Dammartin | C2: arc | D2: Printed 21667.4530; its own log 4.33580.78830 gives 21667.4540 (1 mm slip in source)
A3: 38 | B3: Bellassise | C3: arc | D3: Left log-sine 4.12404.14756 and right log 4.12404.27126 differ by 1.237e-6; arc-sine correction should be 1.201e-6 (≈1 mm inconsistency in source; printed arc follows the right-hand log)
A4: 40 | B4: Brie | C4: logsinSide | D4: Printed 3.96319.10176 is 1.0e-6 too large for the triangle (Montlhéri side and the base from triangle 39 agree); Brie–Tour de Croy is a side branch, not on the main chain
A5: 41 | B5: Montlhéri | C5: arc | D5: Printed arc 12374.2130 (log 4.09251.75892) is 5 mm longer than the left-page log-sine 4.09251.63762 implies (12374.2081); chain uses log-sines
A6: 44 | B6: Malvoisine | C6: arc | D6: Montlhéri–Torfou printed 6212.1595 (chord 6212.1579), but both its logs (3.79323.29524 / .32141) and its reuse as base of triangle 46 give 6212.0253: misprint of 0.134 toise (26 cm) in the arc and chord columns only
A7: 50 | B7: Bromeille | C7: logsinA | D7: Printed log-sine 9.95884.42207 corresponds to 114°33′6.0″, printed angle is 114°33′4.0″ (secondary point; log is the one consistent with the chain)
A8: 51 | B8: Méréville | C8: logsinA | D8: Printed log-sine 9.99969.66886 corresponds to 92°8′28″ vs printed 92°8′22″ (secondary point, near 90° so effect on sides is 4e-8 in log)
A9: 52 | B9: Pithiviers | C9: logsinA | D9: Printed log-sine 9.99975.66805 corresponds to 91°55′3.92″ vs printed 91°55′6.18″; sides follow the log
A10: 53 | B10: Châtillon | C10: logsinA | D10: Printed log-sine 9.99794.75018 corresponds to 95°33′57.67″ vs printed 95°33′52.13″ (seconds digit partly illegible, value fixed by the angle sum); sides follow the log
A11: 54 | B11: Châtillon | C11: logsinA | D11: Printed log-sine 9.99940.30128 corresponds to 93°0′12.62″ vs printed angle 93°0′17.48″; sides follow the log
A12: 55 | B12: Châtillon | C12: arc | D12: Châteauneuf–Orléans printed arc 12053.9075 (right log 4.08112.78539) is 1.7 cm shorter than the left-page log-sine implies (12053.9241); chain (triangle 56) follows the left page
A13: 56 | B13: Orléans | C13: arc | D13: Printed arc 13880.6212 vs its log 4.14240.88018 = 13880.6180 (3 mm)
... A33: 43 | B33: Malvoisine | C33: metres | D33: Lieursaint–Melun (the Melun base) printed 11832.4063 m; 6075.9001 t × 1.949037 = 11842.152 m. Misprint of 9.7 m in the metres column (the other row converts correctly)
A35: How the transcription was checked
A36: Every number was read from the e-rara scan (ETH-Bibliothek Zürich, Rar 10260). Each row was tested against: (1) log sin of the printed angle; (2) the sine rule within the triangle; (3) the base side carried from an earlier triangle; (4) the printed arc against its logarithm; (5) the angle sum against the excess. Values that failed were re-read; the entries above are the ones that still fail and were confirmed as printed.
A37: The left-page logarithms are authoritative: Delambre states that all calculations were made on the logarithms and that the toise and metre columns are “pour la curiosité du lecteur” (p. 703). Most arc misprints fall in triangles 44–100, the triangles whose angles he adjusted, which suggests the toise columns were not all recomputed afterwards.
A38: Signal heights and the “distance vraie” column were not transcribed. Triangles 67–68 (Bourges tower ties) are printed without logarithms. The 13 secondary triangles on pp. 840–844 are not included.
